Checking for updates...
Running latest version...
Press ENTER to run the Lab Check...test_a (__main__.lab0a)
[Lab 1] - [Investigation 1] - [Task 1] - github repository - Test for git clone ... FAIL

======================================================================
FAIL: test_a (__main__.lab0a)
[Lab 1] - [Investigation 1] - [Task 1] - github repository - Test for git clone
----------------------------------------------------------------------
Traceback (most recent call last):
  File "./CheckLab1.py", line 63, in test_a
    self.assertTrue(dirs_exist, msg=error_output)
AssertionError: False is not true : ('your local git close directory cannot be found(HINT: make sure you have clone your github repository under the correct directory)', ['~/ops435/lab1/eelmi'])

----------------------------------------------------------------------
Ran 1 test in 0.002s

FAILED (failures=1)
OPS435 Lab Report - System Information for running ./CheckLab1.py
=================================================================
    User login name: eelmi
    Linux system name: mtrx-node01pd.dcm.senecacollege.ca
    Linux system version: CentOS Linux release 7.9.2009 (Core)
    Python executable: /usr/bin/python3
    Python version: 368
    OS Platform: linux
    Working Directory: /home/eelmi/ops435/lab1
    Start at: Thu Apr  1 21:15:00 2021
=================================================================
